Traceback (most recent call last):
  File "/usr/local/lib/python3.8/dist-packages/jupyter_cache/executors/utils.py", line 58, in single_nb_execution
    executenb(
  File "/usr/local/lib/python3.8/dist-packages/nbclient/client.py", line 1204, in execute
    return NotebookClient(nb=nb, resources=resources, km=km, **kwargs).execute()
  File "/usr/local/lib/python3.8/dist-packages/nbclient/util.py", line 84, in wrapped
    return just_run(coro(*args, **kwargs))
  File "/usr/local/lib/python3.8/dist-packages/nbclient/util.py", line 62, in just_run
    return loop.run_until_complete(coro)
  File "/usr/lib/python3.8/asyncio/base_events.py", line 616, in run_until_complete
    return future.result()
  File "/usr/local/lib/python3.8/dist-packages/nbclient/client.py", line 663, in async_execute
    await self.async_execute_cell(
  File "/usr/local/lib/python3.8/dist-packages/nbclient/client.py", line 965, in async_execute_cell
    await self._check_raise_for_error(cell, cell_index, exec_reply)
  File "/usr/local/lib/python3.8/dist-packages/nbclient/client.py", line 862, in _check_raise_for_error
    raise CellExecutionError.from_cell_and_msg(cell, exec_reply_content)
nbclient.exceptions.CellExecutionError: An error occurred while executing the following cell:
------------------
import mysql.connector
import pandas as pd

mydb = mysql.connector.connect(
    host="localhost",
    port="3306",
    database="prosain{200411100086}",
    user="root",
    password=""
)
mycursor = mydb.cursor()
query = "SELECT petalwidth, class FROM iris_arff"
df = pd.read_sql(query, mydb)
df
------------------

[0;31m[0m
[0;31mMySQLInterfaceError[0mTraceback (most recent call last)
[0;32m/usr/local/lib/python3.8/dist-packages/mysql/connector/connection_cext.py[0m in [0;36m_open_connection[0;34m(self)[0m
[1;32m    287[0m         [0;32mtry[0m[0;34m:[0m[0;34m[0m[0;34m[0m[0m
[0;32m--> 288[0;31m             [0mself[0m[0;34m.[0m[0m_cmysql[0m[0;34m.[0m[0mconnect[0m[0;34m([0m[0;34m**[0m[0mcnx_kwargs[0m[0;34m)[0m[0;34m[0m[0;34m[0m[0m
[0m[1;32m    289[0m             [0mself[0m[0;34m.[0m[0m_cmysql[0m[0;34m.[0m[0mconverter_str_fallback[0m [0;34m=[0m [0mself[0m[0;34m.[0m[0m_converter_str_fallback[0m[0;34m[0m[0;34m[0m[0m

[0;31mMySQLInterfaceError[0m: Can't connect to MySQL server on 'localhost:3306' (99)

The above exception was the direct cause of the following exception:

[0;31mDatabaseError[0mTraceback (most recent call last)
[0;32m<ipython-input-2-2b5bbe763c41>[0m in [0;36m<module>[0;34m[0m
[1;32m      2[0m [0;32mimport[0m [0mpandas[0m [0;32mas[0m [0mpd[0m[0;34m[0m[0;34m[0m[0m
[1;32m      3[0m [0;34m[0m[0m
[0;32m----> 4[0;31m mydb = mysql.connector.connect(
[0m[1;32m      5[0m     [0mhost[0m[0;34m=[0m[0;34m"localhost"[0m[0;34m,[0m[0;34m[0m[0;34m[0m[0m
[1;32m      6[0m     [0mport[0m[0;34m=[0m[0;34m"3306"[0m[0;34m,[0m[0;34m[0m[0;34m[0m[0m

[0;32m/usr/local/lib/python3.8/dist-packages/mysql/connector/pooling.py[0m in [0;36mconnect[0;34m(*args, **kwargs)[0m
[1;32m    291[0m [0;34m[0m[0m
[1;32m    292[0m     [0;32mif[0m [0mCMySQLConnection[0m [0;32mand[0m [0;32mnot[0m [0muse_pure[0m[0;34m:[0m[0;34m[0m[0;34m[0m[0m
[0;32m--> 293[0;31m         [0;32mreturn[0m [0mCMySQLConnection[0m[0;34m([0m[0;34m*[0m[0margs[0m[0;34m,[0m [0;34m**[0m[0mkwargs[0m[0;34m)[0m[0;34m[0m[0;34m[0m[0m
[0m[1;32m    294[0m     [0;32mreturn[0m [0mMySQLConnection[0m[0;34m([0m[0;34m*[0m[0margs[0m[0;34m,[0m [0;34m**[0m[0mkwargs[0m[0;34m)[0m[0;34m[0m[0;34m[0m[0m
[1;32m    295[0m [0;34m[0m[0m

[0;32m/usr/local/lib/python3.8/dist-packages/mysql/connector/connection_cext.py[0m in [0;36m__init__[0;34m(self, **kwargs)[0m
[1;32m    116[0m [0;34m[0m[0m
[1;32m    117[0m         [0;32mif[0m [0mkwargs[0m[0;34m:[0m[0;34m[0m[0;34m[0m[0m
[0;32m--> 118[0;31m             [0mself[0m[0;34m.[0m[0mconnect[0m[0;34m([0m[0;34m**[0m[0mkwargs[0m[0;34m)[0m[0;34m[0m[0;34m[0m[0m
[0m[1;32m    119[0m [0;34m[0m[0m
[1;32m    120[0m     [0;32mdef[0m [0m_add_default_conn_attrs[0m[0;34m([0m[0mself[0m[0;34m)[0m [0;34m->[0m [0;32mNone[0m[0;34m:[0m[0;34m[0m[0;34m[0m[0m

[0;32m/usr/local/lib/python3.8/dist-packages/mysql/connector/abstracts.py[0m in [0;36mconnect[0;34m(self, **kwargs)[0m
[1;32m   1176[0m [0;34m[0m[0m
[1;32m   1177[0m         [0mself[0m[0;34m.[0m[0mdisconnect[0m[0;34m([0m[0;34m)[0m[0;34m[0m[0;34m[0m[0m
[0;32m-> 1178[0;31m         [0mself[0m[0;34m.[0m[0m_open_connection[0m[0;34m([0m[0;34m)[0m[0;34m[0m[0;34m[0m[0m
[0m[1;32m   1179[0m         [0;31m# Server does not allow to run any other statement different from ALTER[0m[0;34m[0m[0;34m[0m[0;34m[0m[0m
[1;32m   1180[0m         [0;31m# when user's password has been expired.[0m[0;34m[0m[0;34m[0m[0;34m[0m[0m

[0;32m/usr/local/lib/python3.8/dist-packages/mysql/connector/connection_cext.py[0m in [0;36m_open_connection[0;34m(self)[0m
[1;32m    291[0m                 [0mself[0m[0;34m.[0m[0mconverter[0m[0;34m.[0m[0mstr_fallback[0m [0;34m=[0m [0mself[0m[0;34m.[0m[0m_converter_str_fallback[0m[0;34m[0m[0;34m[0m[0m
[1;32m    292[0m         [0;32mexcept[0m [0mMySQLInterfaceError[0m [0;32mas[0m [0merr[0m[0;34m:[0m[0;34m[0m[0;34m[0m[0m
[0;32m--> 293[0;31m             raise get_mysql_exception(
[0m[1;32m    294[0m                 [0mmsg[0m[0;34m=[0m[0merr[0m[0;34m.[0m[0mmsg[0m[0;34m,[0m [0merrno[0m[0;34m=[0m[0merr[0m[0;34m.[0m[0merrno[0m[0;34m,[0m [0msqlstate[0m[0;34m=[0m[0merr[0m[0;34m.[0m[0msqlstate[0m[0;34m[0m[0;34m[0m[0m
[1;32m    295[0m             ) from err

[0;31mDatabaseError[0m: 2003 (HY000): Can't connect to MySQL server on 'localhost:3306' (99)
DatabaseError: 2003 (HY000): Can't connect to MySQL server on 'localhost:3306' (99)

